Workbook

Sheet Farmacias
A1: NOMBRE FARMACIA | B1: CIUDAD | C1: ZONA | D1: PRIORIDAD | E1: EMPLEADOS | F1: ESTADO DEL PROCESO | G1: ESTADO DEL CONTACTO | H1: TELEFONO | I1: EMAIL | J1: ULTIMA INTERACCION | K1: PROXIMA ACCION | L1: RESULTADO ULTIMO COTACTO | M1: NOTAS
A2: PARRA ASTORGANO, Mª DOLORES | B2: VALLADOLID | C2: ARTURO EYRIES | D2: BAJA | E2: 46240 | F2: Prospecto | G2: No contactado | H2: 663 081 209 | I2: info@farmaciaarturoeyries.es
A3: TEJEDOR TOQUERO, MARÍA TERESA | B3: VALLADOLID | C3: ARTURO EYRIES | D3: MEDIA | E3: 1 | F3: Prospecto | G3: No contactado | H3: 983 471 881 | I3: farmaciatejedortoquero@gmail.com
A4: RODRÍGUEZ CARRASCAL, JAVIER | B4: VALLADOLID | C4: ARTURO EYRIES | F4: Prospecto | G4: No contactado | H4: 983 23 61 14
A5: HERRERO VACA, MARÍA | B5: VALLADOLID | C5: ARTURO EYRIES | F5: Prospecto | G5: No contactado | H5: 983 231 098 | I5: mariaherrerovaca@gmail.com
A6: GARCÍA VELASCO, ROSA Mª | B6: VALLADOLID | C6: ARTURO EYRIES | D6: BAJA | E6: 46083 | F6: Prospecto | G6: No contactado | H6: 983 23 36 92
A7: SERRANO PLAZA, Mª LUISA | B7: VALLADOLID | C7: ARTURO EYRIES | D7: ALTA | F7: Prospecto | G7: No contactado | H7: 983 233 572 | I7: marialuisaserrano@redfarma.org
A8: ESCUDERO DÍEZ, MARIA LUISA | B8: VALLADOLID | C8: ARTURO EYRIES | D8: ALTA | F8: Prospecto | G8: No contactado | H8: 983 66 51 11
A9: COLMENERO DÍEZ, MARIA AUXILIADORA | B9: VALLADOLID | C9: ARTURO EYRIES | D9: BAJA | E9: 46114 | F9: Prospecto | G9: No contactado
A10: VIDAL CORCOBA, ROSARIO SANZ VIDAL, MIGUEL ÁNGEL | B10: VALLADOLID | C10: BARRIO ESPAÑA | F10: Prospecto | G10: No contactado
A11: CALZÓN DUEÑAS, LAURA | B11: VALLADOLID | C11: BARRIO ESPAÑA | F11: Prospecto | G11: No contactado
A12: PÉREZ AMPUDIA, Mª DEL MILAGRO | B12: VALLADOLID | C12: CAMPO GRANDE | F12: Prospecto | G12: No contactado
A13: RODRÍGUEZ BLANCO, EMMA | B13: VALLADOLID | C13: CAMPO GRANDE | D13: MEDIA | E13: 46054 | F13: Prospecto | G13: No contactado
A14: LÓPEZ ESCORIAL, CRISTINA | B14: VALLADOLID | C14: CAMPO GRANDE | F14: Prospecto | G14: No contactado
A15: RUIZ ALONSO, JESÚS ÁNGEL RUIZ RAMOS, JAVIER | B15: VALLADOLID | C15: CAMPO GRANDE | F15: Prospecto | G15: No contactado
A16: SANABRIA MURCIEGO, JOSÉ MIGUEL | B16: VALLADOLID | C16: CAMPO GRANDE | F16: Prospecto | G16: No contactado
A17: PASCUAL PAÍNO, JESÚS MANUEL | B17: VALLADOLID | C17: CAMPO GRANDE | D17: MEDIA | E17: 2 | F17: Prospecto | G17: No contactado
A18: SANTIAGO SASTRE, GENOVEVA | B18: VALLADOLID | C18: CAMPO GRANDE | D18: ALTA | E18: 2 | F18: Prospecto | G18: No contactado
A19: RODRÍGUEZ MARTÍN, Mª TERESA | B19: VALLADOLID | C19: CANTERAC | F19: Prospecto | G19: No contactado
A20: NAVAS MUÑOZ, AURORA | B20: VALLADOLID | C20: CANTERAC | D20: MEDIA | F20: Prospecto | G20: No contactado
A21: LLANES GARCÍA, LUIS MANUEL | B21: VALLADOLID | C21: CANTERAC | D21: MEDIA | E21: 46083 | F21: Prospecto | G21: No contactado
A22: GÓMEZ ARQUEROS, EDUARDO | B22: VALLADOLID | C22: CANTERAC | F22: Prospecto | G22: No contactado
A23: SECO DOMÍNGUEZ, Mª NIEVES | B23: VALLADOLID | C23: CANTERAC | F23: Prospecto | G23: No contactado
A24: BENÍTEZ VILLAR, BLANCA | B24: VALLADOLID | C24: CANTERAC | D24: ALTA | E24: 46114 | F24: Prospecto | G24: No contactado
A25: COUPEAU BORRÁS, PABLO JESÚS | B25: VALLADOLID | C25: CENTRO-GAMAZO | F25: Prospecto | G25: No contactado
A26: FUENTE MOREIRO, CONCEPCIÓN DE LA | B26: VALLADOLID | C26: CENTRO-GAMAZO | F26: Prospecto | G26: No contactado
A27: LÓPEZ-CASAMAYOR JUSTICIA, MARÍA DE LA PAZ | B27: VALLADOLID | C27: CENTRO-GAMAZO | F27: Prospecto | G27: No contactado
A28: PRESA VALENTÍN, VICENTE | B28: VALLADOLID | C28: CENTRO-GAMAZO | F28: Prospecto | G28: No contactado
A29: SOBRINO HEBRERO, CARMEN Mª | B29: VALLADOLID | C29: CENTRO-GAMAZO | F29: Prospecto | G29: No contactado
A30: ARROITA GARCÍA, FERNANDO | B30: VALLADOLID | C30: CENTRO-GAMAZO | F30: Prospecto | G30: No contactado
A31: CRESPO PÉREZ, JOSE LUIS | B31: VALLADOLID | C31: CENTRO-GAMAZO | D31: BAJA | E31: 46177 | F31: Prospecto | G31: No contactado
A32: GÓMEZ HERNÁNDEZ, ÁNGEL | B32: VALLADOLID | C32: CENTRO-GAMAZO | F32: Prospecto | G32: No contactado
A33: FURONES GIL, FRANCISCO JAVIER | B33: VALLADOLID | C33: CENTRO-GAMAZO | F33: Prospecto | G33: No contactado
A34: FERNÁNDEZ FERNÁNDEZ, VIRGINIA | B34: VALLADOLID | C34: CENTRO-GAMAZO | F34: Prospecto | G34: No contactado
A35: GARCÍA BLANCO, Mª ISABEL | B35: VALLADOLID | C35: CENTRO-GAMAZO | F35: Prospecto | G35: No contactado
A36: MARTÍNEZ DEL CASTILLO, JAVIER | B36: VALLADOLID | C36: CENTRO-GAMAZO | F36: Prospecto | G36: No contactado
A37: MARTÍNEZ MUÑOZ, MÓNICA | B37: VALLADOLID | C37: CENTRO-GAMAZO | F37: Prospecto | G37: No contactado
A38: ÁLVAREZ CARBALLO, SALVIA | B38: VALLADOLID | C38: CENTRO-GAMAZO | D38: ALTA | E38: 46114 | F38: Prospecto | G38: No contactado
A39: RODRÍGUEZ BALLESTERO, MARIA | B39: VALLADOLID | C39: CENTRO-GAMAZO | F39: Prospecto | G39: No contactado
A40: ARAUJO VALLE, MARTA | B40: VALLADOLID | C40: CENTRO-GAMAZO | D40: MEDIA | E40: 46083 | F40: Prospecto | G40: No contactado
...

Sheet Reuniones
A1: Farmacia | B1: Tipo | C1: Fecha | D1: Resultado | E1: Objeción | F1: Motivo positivo | G1: Resumen | H1: Próxima acción

Sheet Auditorias
A1: Farmacia | B1: Estado | C1: Resultado | D1: Fecha venta | E1: Fecha entrega | F1: Horas totales

Sheet Clientes
A1: Farmacia | B1: Tipo servicio | C1: Fecha inicio | D1: Estado | E1: Cuota mensual (€) | F1: Último contacto | G1: Motivo baja

Sheet Dashboard
A1: CRM FARMACIAS — DASHBOARD COMERCIAL
A3: Indicador | B3: Valor | C3: Lectura | E3: Provincia | F3: Total
A4: Farmacias totales | B4: =COUNTA(Farmacias!A2:A600) -> 316 | C4: Base comercial cargada | E4: Valladolid | F4: =COUNTIF(Farmacias!B2:B600,"Valladolid") -> 278
A5: Contactadas | B5: =COUNTIF(Farmacias!F2:F600,"Contactada") -> 0 | C5: Primer contacto realizado | E5: Palencia | F5: =COUNTIF(Farmacias!B2:B600,"Palencia") -> 38
A6: Reuniones | B6: =COUNTIF(Farmacias!F2:F600,"Reunión") -> 0 | C6: Interés cualificado | E6: Salamanca | F6: =COUNTIF(Farmacias!B2:B600,"Salamanca") -> 0
A7: Auditorías | B7: =COUNTIF(Farmacias!F2:F600,"Auditoría") -> 0 | C7: Oportunidad avanzada
A8: Propuestas | B8: =COUNTIF(Farmacias!F2:F600,"Propuesta enviada") -> 0 | C8: Oferta enviada
A9: Clientes activos | B9: =COUNTIF(Farmacias!F2:F600,"Cliente activo") -> 0 | C9: MRR real | E9: Prioridad | F9: Total
A10: MRR estimado ponderado | B10: =SUM(Farmacias!U2:U600) -> 0 | C10: Forecast ponderado | E10: ALTA | F10: =COUNTIF(Farmacias!D2:D600,"ALTA") -> 23
A11: Tasa reunión/contacto | B11: =IFERROR(B4/B3,0) -> 0 | C11: Conversión inicial | E11: MEDIA | F11: =COUNTIF(Farmacias!D2:D600,"MEDIA") -> 46
A12: Tasa cliente/auditoría | B12: =IFERROR(B7/B5,0) -> 0 | C12: Conversión final | E12: BAJA | F12: =COUNTIF(Farmacias!D2:D600,"BAJA") -> 44
E13: Sin definir | F13: =COUNTBLANK(Farmacias!D2:D600) -> 486
A15: Fase | B15: Nº farmacias | C15: % sobre total
A16: Prospecto | B16: =COUNTIF(Farmacias!F2:F600,"Prospecto") -> 316 | C16: =IFERROR(B16/$B$4,0) -> 1 | E16: Próxima acción | F16: Total
A17: Contactada | B17: =COUNTIF(Farmacias!F2:F600,"Contactada") -> 0 | C17: =IFERROR(B17/$B$4,0) -> 0 | E17: Visitar | F17: =COUNTIF(Farmacias!AA2:AA600,"Visitar") -> 0
A18: Reunión | B18: =COUNTIF(Farmacias!F2:F600,"Reunión") -> 0 | C18: =IFERROR(B18/$B$4,0) -> 0 | E18: Seguimiento | F18: =COUNTIF(Farmacias!AA2:AA600,"Seguimiento") -> 0
A19: Auditoría | B19: =COUNTIF(Farmacias!F2:F600,"Auditoría") -> 0 | C19: =IFERROR(B19/$B$4,0) -> 0 | E19: Programada | F19: =COUNTIF(Farmacias!AA2:AA600,"Programada") -> 0
A20: Propuesta enviada | B20: =COUNTIF(Farmacias!F2:F600,"Propuesta enviada") -> 0 | C20: =IFERROR(B20/$B$4,0) -> 0 | E20: Mantenimiento | F20: =COUNTIF(Farmacias!AA2:AA600,"Mantenimiento") -> 0
A21: Cliente activo | B21: =COUNTIF(Farmacias!F2:F600,"Cliente activo") -> 0 | C21: =IFERROR(B21/$B$4,0) -> 0
A22: Perdido | B22: =COUNTIF(Farmacias!F2:F600,"Perdido") -> 0 | C22: =IFERROR(B22/$B$4,0) -> 0
